<sdf version='1.7'>
  <world name='default'>
    <light name='sun' type='directional'>
      <cast_shadows>1</cast_shadows>
      <pose>0 0 10 0 -0 0</pose>
      <diffuse>0.8 0.8 0.8 1</diffuse>
      <specular>0.1 0.1 0.1 1</specular>
      <attenuation>
        <range>1000</range>
        <constant>0.9</constant>
        <linear>0.01</linear>
        <quadratic>0.001</quadratic>
      </attenuation>
      <direction>-0.5 0.5 -1</direction>
      <spot>
        <inner_angle>0</inner_angle>
        <outer_angle>0</outer_angle>
        <falloff>0</falloff>
      </spot>
    </light>
    <model name='ground_plane'>
      <static>1</static>
      <link name='link'>
        <collision name='collision'>
          <geometry>
            <plane>
              <normal>0 0 1</normal>
              <size>100 100</size>
            </plane>
          </geometry>
          <surface>
            <friction>
              <ode>
                <mu>100</mu>
                <mu2>50</mu2>
              </ode>
              <torsional>
                <ode/>
              </torsional>
            </friction>
            <contact>
              <ode/>
            </contact>
            <bounce/>
          </surface>
          <max_contacts>10</max_contacts>
        </collision>
        <visual name='visual'>
          <cast_shadows>0</cast_shadows>
          <geometry>
            <plane>
              <normal>0 0 1</normal>
              <size>100 100</size>
            </plane>
          </geometry>
          <material>
            <script>
              <uri>file://media/materials/scripts/gazebo.material</uri>
              <name>Gazebo/Grey</name>
            </script>
          </material>
        </visual>
        <self_collide>0</self_collide>
        <kinematic>0</kinematic>
        <gravity>1</gravity>
        <enable_wind>0</enable_wind>
      </link>
    </model>
    <gravity>0 0 -9.8</gravity>
    <magnetic_field>6e-06 2.3e-05 -4.2e-05</magnetic_field>
    <atmosphere type='adiabatic'/>
    <physics name='default_physics' default='0' type='ode'>
      <max_step_size>0.001</max_step_size>
      <real_time_factor>1</real_time_factor>
      <real_time_update_rate>1000</real_time_update_rate>
    </physics>
    <scene>
      <ambient>0.4 0.4 0.4 1</ambient>
      <background>0.7 0.7 0.7 1</background>
      <shadows>1</shadows>
    </scene>
    <spherical_coordinates>
      <surface_model>EARTH_WGS84</surface_model>
      <latitude_deg>0</latitude_deg>
      <longitude_deg>0</longitude_deg>
      <elevation>0</elevation>
      <heading_deg>0</heading_deg>
    </spherical_coordinates>
    <model name='circle_road_0'>
      <link name='link_0'>
        <pose>0 0 0 0 -0 0</pose>
        <inertial>
          <mass>1</mass>
          <inertia>
            <ixx>0.166667</ixx>
            <ixy>0</ixy>
            <ixz>0</ixz>
            <iyy>0.166667</iyy>
            <iyz>0</iyz>
            <izz>0.166667</izz>
          </inertia>
        </inertial>
        <visual name='visual'>
          <pose>0 0 0 0 -0 0</pose>
          <geometry>
            <mesh>
              <uri>file:///home/brent/Documents/autonomous-driving/ros/src/qcar_gazebo/model_/circle_road/meshes/circle_road.dae</uri>
              <scale>0.5 0.5 0.5</scale>
            </mesh>
          </geometry>
          <material>
            <lighting>1</lighting>
          </material>
          <cast_shadows>1</cast_shadows>
          <transparency>0</transparency>
        </visual>
        <collision name='collision'>
          <laser_retro>0</laser_retro>
          <max_contacts>10</max_contacts>
          <pose>0 0 0 0 -0 0</pose>
          <geometry>
            <mesh>
              <uri>file:///home/brent/Documents/autonomous-driving/ros/src/qcar_gazebo/model_/circle_road/meshes/circle_road.dae</uri>
              <scale>1 1 1</scale>
            </mesh>
          </geometry>
          <surface>
            <friction>
              <ode>
                <mu>1</mu>
                <mu2>1</mu2>
                <fdir1>0 0 0</fdir1>
                <slip1>0</slip1>
                <slip2>0</slip2>
              </ode>
              <torsional>
                <coefficient>1</coefficient>
                <patch_radius>0</patch_radius>
                <surface_radius>0</surface_radius>
                <use_patch_radius>1</use_patch_radius>
                <ode>
                  <slip>0</slip>
                </ode>
              </torsional>
            </friction>
            <bounce>
              <restitution_coefficient>0</restitution_coefficient>
              <threshold>1e+06</threshold>
            </bounce>
            <contact>
              <collide_without_contact>0</collide_without_contact>
              <collide_without_contact_bitmask>1</collide_without_contact_bitmask>
              <collide_bitmask>1</collide_bitmask>
              <ode>
                <soft_cfm>0</soft_cfm>
                <soft_erp>0.2</soft_erp>
                <kp>1e+13</kp>
                <kd>1</kd>
                <max_vel>0.01</max_vel>
                <min_depth>0</min_depth>
              </ode>
              <bullet>
                <split_impulse>1</split_impulse>
                <split_impulse_penetration_threshold>-0.01</split_impulse_penetration_threshold>
                <soft_cfm>0</soft_cfm>
                <soft_erp>0.2</soft_erp>
                <kp>1e+13</kp>
                <kd>1</kd>
              </bullet>
            </contact>
          </surface>
        </collision>
        <self_collide>0</self_collide>
        <kinematic>0</kinematic>
        <gravity>1</gravity>
        <enable_wind>0</enable_wind>
      </link>
      <static>1</static>
      <allow_auto_disable>1</allow_auto_disable>
      <pose>-0.029725 0.041294 0 0 -0 0</pose>
    </model>
    <state world_name='default'>
      <sim_time>316 346000000</sim_time>
      <real_time>200 346169106</real_time>
      <wall_time>1645734959 200052905</wall_time>
      <iterations>197652</iterations>
      <model name='Stop Sign'>
        <pose>4.99213 -0.732299 0 0 0 -1.57035</pose>
        <scale>1 1 1</scale>
        <link name='link'>
          <pose>4.99213 -0.732299 0 0 0 -1.57035</pose>
          <velocity>0 0 0 0 -0 0</velocity>
          <acceleration>0 0 0 0 -0 0</acceleration>
          <wrench>0 0 0 0 -0 0</wrench>
        </link>
      </model>
      <model name='circle_road_0'>
        <pose>-0.637324 -0.968906 0 0 -0 0</pose>
        <scale>1 1 1</scale>
        <link name='link_0'>
          <pose>-0.637324 -0.968906 0 0 -0 0</pose>
          <velocity>0 0 0 0 -0 0</velocity>
          <acceleration>0 0 0 0 -0 0</acceleration>
          <wrench>0 0 0 0 -0 0</wrench>
        </link>
      </model>
      <model name='ground_plane'>
        <pose>0 0 0 0 -0 0</pose>
        <scale>1 1 1</scale>
        <link name='link'>
          <pose>0 0 0 0 -0 0</pose>
          <velocity>0 0 0 0 -0 0</velocity>
          <acceleration>0 0 0 0 -0 0</acceleration>
          <wrench>0 0 0 0 -0 0</wrench>
        </link>
      </model>
      <model name='qcar'>
        <pose>2.25397 -0.40421 0.066 -0.001461 0.000279 -0.05623</pose>
        <scale>1 1 1</scale>
        <link name='base'>
          <pose>2.25397 -0.40421 0.066 -0.001461 0.000279 -0.05623</pose>
          <velocity>-0.000227 -0.000115 -4.5e-05 -0.005615 0.004642 -0.000472</velocity>
          <acceleration>0.949174 1.26398 -1.17924 -1.5749 0.724806 2.05017</acceleration>
          <wrench>0.630252 0.839279 -0.783013 0 -0 0</wrench>
        </link>
        <link name='hubfl'>
          <pose>2.38652 -0.355634 0.099263 -0.00146 0.000279 -0.056231</pose>
          <velocity>-2.4e-05 6.8e-05 -0.001051 -0.005766 0.004657 -0.000486</velocity>
          <acceleration>0.003241 0.128719 -2.09638 -1.93759 0.172703 2.32019</acceleration>
          <wrench>0.000324 0.012872 -0.209638 0 -0 0</wrench>
        </link>
        <link name='hubfr'>
          <pose>2.38023 -0.467257 0.099425 -0.001459 0.00028 -0.056229</pose>
          <velocity>-0.000116 5.2e-05 -0.000113 -0.00572 0.004377 -0.000489</velocity>
          <acceleration>-0.165336 0.097843 -0.227452 -1.85757 0.752585 2.01682</acceleration>
          <wrench>-0.016534 0.009784 -0.022745 0 -0 0</wrench>
        </link>
        <link name='lidar'>
          <pose>2.24175 -0.403737 0.227524 0.000341 -0.001448 -2.04663</pose>
          <velocity>0.000521 0.000784 5e-06 0.009232 0.064445 -2.37155</velocity>
          <acceleration>1.09586 1.52691 -2.8e-05 -1.74549 0.485138 3.13272</acceleration>
          <wrench>0.109586 0.152691 -3e-06 0 -0 0</wrench>
        </link>
        <link name='wheelfl'>
          <pose>2.38652 -0.355635 0.099263 0.011191 -1.43984 3.07267</pose>
          <velocity>-3.6e-05 0.000195 -0.001135 -0.005904 0.000338 -0.000423</velocity>
          <acceleration>-0.032005 0.383724 -2.26471 0.92489 0.672939 -0.655809</acceleration>
          <wrench>-0.003201 0.038372 -0.226471 0 -0 0</wrench>
        </link>
        <link name='wheelfr'>
          <pose>2.38023 -0.467255 0.099425 -3.14014 0.058206 3.08545</pose>
          <velocity>-0.000156 0.00019 -2.5e-05 -0.005952 -0.005046 -0.000507</velocity>
          <acceleration>-0.245584 0.379456 -0.043845 -2.1904 -1.45986 1.9795</acceleration>
          <wrench>-0.024558 0.037946 -0.004384 0 -0 0</wrench>
        </link>
        <link name='wheelrl'>
          <pose>2.12969 -0.340978 0.099334 0.003996 1.19532 3.08749</pose>
          <velocity>9e-05 0.000176 0.000184 -0.005341 0.003727 -0.00089</velocity>
          <acceleration>0.22067 0.337378 0.357172 -0.990644 0.978494 1.47609</acceleration>
          <wrench>0.022067 0.033738 0.035717 0 -0 0</wrench>
        </link>
        <link name='wheelrr'>
          <pose>2.12338 -0.452999 0.099498 -0.001652 -0.484919 -0.05546</pose>
          <velocity>-9.4e-05 0.00012 0.000822 -0.005557 0.004709 -0.000442</velocity>
          <acceleration>-0.122498 0.21074 1.61682 -1.52749 0.283666 2.34014</acceleration>
          <wrench>-0.01225 0.021074 0.161682 0 -0 0</wrench>
        </link>
      </model>
      <light name='sun'>
        <pose>0 0 10 0 -0 0</pose>
      </light>
    </state>
    <gui fullscreen='0'>
      <camera name='user_camera'>
        <pose>-19.7985 -1.52644 6.03086 -0 0.355644 0.140193</pose>
        <view_controller>orbit</view_controller>
        <projection_type>perspective</projection_type>
      </camera>
    </gui>
    <wind/>
    <model name='qcar'>
      <link name='base'>
        <inertial>
          <pose>0.069384 0.04166 0.141807 0 -0 0</pose>
          <mass>0.664</mass>
          <inertia>
            <ixx>0.00745304</ixx>
            <ixy>-0.000340307</ixy>
            <ixz>-0.00115836</ixz>
            <iyy>0.00443318</iyy>
            <iyz>-0.00069552</iyz>
            <izz>0.00565036</izz>
          </inertia>
        </inertial>
        <collision name='base_collision'>
          <pose>0 0 0 0 -0 0</pose>
          <geometry>
            <mesh>
              <scale>0.001 0.001 0.001</scale>
              <uri>/home/brent/Documents/autonomous-driving/ros/src/qcar_gazebo/meshes/QCarBody.stl</uri>
            </mesh>
          </geometry>
          <max_contacts>10</max_contacts>
          <surface>
            <contact>
              <ode/>
            </contact>
            <bounce/>
            <friction>
              <torsional>
                <ode/>
              </torsional>
              <ode/>
            </friction>
          </surface>
        </collision>
        <collision name='base_fixed_joint_lump__camera_link_collision_1'>
          <pose>0.081686 0.031547 0.16695 0 -0 0</pose>
          <geometry>
            <box>
              <size>0.02505 0.09 0.025</size>
            </box>
          </geometry>
          <surface>
            <contact>
              <ode>
                <kp>1e+13</kp>
                <kd>1</kd>
              </ode>
            </contact>
            <friction>
              <ode>
                <mu2>1</mu2>
                <fdir1>0 0 0</fdir1>
              </ode>
              <torsional>
                <ode/>
              </torsional>
            </friction>
            <bounce/>
          </surface>
          <max_contacts>10</max_contacts>
        </collision>
        <visual name='base_visual'>
          <pose>0 0 0 0 -0 0</pose>
          <geometry>
            <mesh>
              <scale>0.001 0.001 0.001</scale>
              <uri>/home/brent/Documents/autonomous-driving/ros/src/qcar_gazebo/meshes/QCarBody.stl</uri>
            </mesh>
          </geometry>
        </visual>
        <visual name='base_fixed_joint_lump__camera_link_visual_1'>
          <pose>0.096586 0.031547 0.16695 1.5708 -0 1.5708</pose>
          <geometry>
            <mesh>
              <scale>1 1 1</scale>
              <uri>/home/brent/Documents/autonomous-driving/ros/src/realsense2_description/meshes/d435.dae</uri>
            </mesh>
          </geometry>
        </visual>
        <self_collide>0</self_collide>
        <enable_wind>0</enable_wind>
        <kinematic>0</kinematic>
        <gravity>1</gravity>
        <sensor name='cameracolor' type='camera'>
          <camera name='camera'>
            <horizontal_fov>1.21126</horizontal_fov>
            <image>
              <width>640</width>
              <height>480</height>
              <format>RGB_INT8</format>
            </image>
            <clip>
              <near>0.1</near>
              <far>100</far>
            </clip>
            <noise>
              <type>gaussian</type>
              <mean>0</mean>
              <stddev>0.007</stddev>
            </noise>
          </camera>
          <always_on>1</always_on>
          <update_rate>30</update_rate>
          <visualize>1</visualize>
          <pose>0.081686 0.049047 0.16695 0 -0 0</pose>
        </sensor>
        <sensor name='cameraired1' type='camera'>
          <camera name='camera'>
            <horizontal_fov>1.48702</horizontal_fov>
            <image>
              <width>1280</width>
              <height>720</height>
              <format>L_INT8</format>
            </image>
            <clip>
              <near>0.1</near>
              <far>100</far>
            </clip>
            <noise>
              <type>gaussian</type>
              <mean>0</mean>
              <stddev>0.05</stddev>
            </noise>
          </camera>
          <always_on>1</always_on>
          <update_rate>90</update_rate>
          <visualize>0</visualize>
          <pose>0.081686 0.049047 0.16695 0 -0 0</pose>
        </sensor>
        <sensor name='cameraired2' type='camera'>
          <camera name='camera'>
            <horizontal_fov>1.48702</horizontal_fov>
            <image>
              <width>1280</width>
              <height>720</height>
              <format>L_INT8</format>
            </image>
            <clip>
              <near>0.1</near>
              <far>100</far>
            </clip>
            <noise>
              <type>gaussian</type>
              <mean>0</mean>
              <stddev>0.05</stddev>
            </noise>
          </camera>
          <always_on>1</always_on>
          <update_rate>90</update_rate>
          <visualize>0</visualize>
          <pose>0.081686 0.049047 0.16695 0 -0 0</pose>
        </sensor>
        <sensor name='cameradepth' type='depth'>
          <camera name='camera'>
            <horizontal_fov>1.48702</horizontal_fov>
            <image>
              <width>1280</width>
              <height>720</height>
            </image>
            <clip>
              <near>0.1</near>
              <far>100</far>
            </clip>
            <noise>
              <type>gaussian</type>
              <mean>0</mean>
              <stddev>0.1</stddev>
            </noise>
          </camera>
          <always_on>1</always_on>
          <update_rate>90</update_rate>
          <visualize>0</visualize>
          <pose>0.081686 0.049047 0.16695 0 -0 0</pose>
        </sensor>
      </link>
      <joint name='base_hubfl_joint' type='revolute'>
        <pose relative_to='base'>0.1296 0.0559 0.03338 0 -0 0</pose>
        <parent>base</parent>
        <child>hubfl</child>
        <axis>
          <xyz>0 0 1</xyz>
          <limit>
            <lower>-0.5236</lower>
            <upper>0.5236</upper>
            <effort>300</effort>
            <velocity>2</velocity>
          </limit>
          <dynamics>
            <damping>0.143</damping>
            <friction>0</friction>
            <spring_reference>0</spring_reference>
            <spring_stiffness>0</spring_stiffness>
          </dynamics>
        </axis>
      </joint>
      <link name='hubfl'>
        <pose relative_to='base_hubfl_joint'>0 0 0 0 -0 0</pose>
        <inertial>
          <pose>0 0 0 0 -0 0</pose>
          <mass>0.1</mass>
          <inertia>
            <ixx>0.001</ixx>
            <ixy>0</ixy>
            <ixz>0</ixz>
            <iyy>0.001</iyy>
            <iyz>0</iyz>
            <izz>0.001</izz>
          </inertia>
        </inertial>
        <collision name='hubfl_collision'>
          <pose>0 0 0 0 -0 0</pose>
          <geometry>
            <mesh>
              <scale>0.001 0.001 0.001</scale>
              <uri>/home/brent/Documents/autonomous-driving/ros/src/qcar_gazebo/meshes/QCarSteeringHubL.stl</uri>
            </mesh>
          </geometry>
          <max_contacts>10</max_contacts>
          <surface>
            <contact>
              <ode/>
            </contact>
            <bounce/>
            <friction>
              <torsional>
                <ode/>
              </torsional>
              <ode/>
            </friction>
          </surface>
        </collision>
        <visual name='hubfl_visual'>
          <pose>0 0 0 0 -0 0</pose>
          <geometry>
            <mesh>
              <scale>0.001 0.001 0.001</scale>
              <uri>/home/brent/Documents/autonomous-driving/ros/src/qcar_gazebo/meshes/QCarSteeringHubL.stl</uri>
            </mesh>
          </geometry>
        </visual>
        <self_collide>0</self_collide>
        <enable_wind>0</enable_wind>
        <kinematic>0</kinematic>
      </link>
      <joint name='hubfl_wheelfl_joint' type='revolute'>
        <pose relative_to='hubfl'>0 0 0 0 -0 3.14</pose>
        <parent>hubfl</parent>
        <child>wheelfl</child>
        <axis>
          <xyz>0 1 0</xyz>
          <limit>
            <lower>-1e+16</lower>
            <upper>1e+16</upper>
          </limit>
          <dynamics>
            <spring_reference>0</spring_reference>
            <spring_stiffness>0</spring_stiffness>
          </dynamics>
        </axis>
      </joint>
      <link name='wheelfl'>
        <pose relative_to='hubfl_wheelfl_joint'>0 0 0 0 -0 0</pose>
        <inertial>
          <pose>0 0 0 0 -0 0</pose>
          <mass>0.1</mass>
          <inertia>
            <ixx>0.001</ixx>
            <ixy>0</ixy>
            <ixz>0</ixz>
            <iyy>0.001</iyy>
            <iyz>0</iyz>
            <izz>0.001</izz>
          </inertia>
        </inertial>
        <collision name='wheelfl_collision'>
          <pose>0 0 0 0 -0 0</pose>
          <geometry>
            <mesh>
              <scale>0.001 0.001 0.001</scale>
              <uri>/home/brent/Documents/autonomous-driving/ros/src/qcar_gazebo/meshes/QCarWheel.stl</uri>
            </mesh>
          </geometry>
          <max_contacts>10</max_contacts>
          <surface>
            <contact>
              <ode/>
            </contact>
            <bounce/>
            <friction>
              <torsional>
                <ode/>
              </torsional>
              <ode/>
            </friction>
          </surface>
        </collision>
        <visual name='wheelfl_visual'>
          <pose>0 0 0 0 -0 0</pose>
          <geometry>
            <mesh>
              <scale>0.001 0.001 0.001</scale>
              <uri>/home/brent/Documents/autonomous-driving/ros/src/qcar_gazebo/meshes/QCarWheel.stl</uri>
            </mesh>
          </geometry>
        </visual>
        <self_collide>0</self_collide>
        <enable_wind>0</enable_wind>
        <kinematic>0</kinematic>
      </link>
      <joint name='base_hubfr_joint' type='revolute'>
        <pose relative_to='base'>0.1296 -0.0559 0.03338 0 -0 0</pose>
        <parent>base</parent>
        <child>hubfr</child>
        <axis>
          <xyz>0 0 1</xyz>
          <limit>
            <lower>-0.5236</lower>
            <upper>0.5236</upper>
            <effort>300</effort>
            <velocity>2</velocity>
          </limit>
          <dynamics>
            <damping>0.143</damping>
            <friction>0</friction>
            <spring_reference>0</spring_reference>
            <spring_stiffness>0</spring_stiffness>
          </dynamics>
        </axis>
      </joint>
      <link name='hubfr'>
        <pose relative_to='base_hubfr_joint'>0 0 0 0 -0 0</pose>
        <inertial>
          <pose>0 0 0 0 -0 0</pose>
          <mass>0.1</mass>
          <inertia>
            <ixx>0.001</ixx>
            <ixy>0</ixy>
            <ixz>0</ixz>
            <iyy>0.001</iyy>
            <iyz>0</iyz>
            <izz>0.001</izz>
          </inertia>
        </inertial>
        <collision name='hubfr_collision'>
          <pose>0 0 0 0 -0 0</pose>
          <geometry>
            <mesh>
              <scale>0.001 0.001 0.001</scale>
              <uri>/home/brent/Documents/autonomous-driving/ros/src/qcar_gazebo/meshes/QCarSteeringHubR.stl</uri>
            </mesh>
          </geometry>
          <max_contacts>10</max_contacts>
          <surface>
            <contact>
              <ode/>
            </contact>
            <bounce/>
            <friction>
              <torsional>
                <ode/>
              </torsional>
              <ode/>
            </friction>
          </surface>
        </collision>
        <visual name='hubfr_visual'>
          <pose>0 0 0 0 -0 0</pose>
          <geometry>
            <mesh>
              <scale>0.001 0.001 0.001</scale>
              <uri>/home/brent/Documents/autonomous-driving/ros/src/qcar_gazebo/meshes/QCarSteeringHubR.stl</uri>
            </mesh>
          </geometry>
        </visual>
        <self_collide>0</self_collide>
        <enable_wind>0</enable_wind>
        <kinematic>0</kinematic>
      </link>
      <joint name='hubfr_wheelfr_joint' type='revolute'>
        <pose relative_to='hubfr'>0 0 0 0 -0 0</pose>
        <parent>hubfr</parent>
        <child>wheelfr</child>
        <axis>
          <xyz>0 1 0</xyz>
          <limit>
            <lower>-1e+16</lower>
            <upper>1e+16</upper>
          </limit>
          <dynamics>
            <spring_reference>0</spring_reference>
            <spring_stiffness>0</spring_stiffness>
          </dynamics>
        </axis>
      </joint>
      <link name='wheelfr'>
        <pose relative_to='hubfr_wheelfr_joint'>0 0 0 0 -0 0</pose>
        <inertial>
          <pose>0 0 0 0 -0 0</pose>
          <mass>0.1</mass>
          <inertia>
            <ixx>0.001</ixx>
            <ixy>0</ixy>
            <ixz>0</ixz>
            <iyy>0.001</iyy>
            <iyz>0</iyz>
            <izz>0.001</izz>
          </inertia>
        </inertial>
        <collision name='wheelfr_collision'>
          <pose>0 0 0 0 -0 0</pose>
          <geometry>
            <mesh>
              <scale>0.001 0.001 0.001</scale>
              <uri>/home/brent/Documents/autonomous-driving/ros/src/qcar_gazebo/meshes/QCarWheel.stl</uri>
            </mesh>
          </geometry>
          <max_contacts>10</max_contacts>
          <surface>
            <contact>
              <ode/>
            </contact>
            <bounce/>
            <friction>
              <torsional>
                <ode/>
              </torsional>
              <ode/>
            </friction>
          </surface>
        </collision>
        <visual name='wheelfr_visual'>
          <pose>0 0 0 0 -0 0</pose>
          <geometry>
            <mesh>
              <scale>0.001 0.001 0.001</scale>
              <uri>/home/brent/Documents/autonomous-driving/ros/src/qcar_gazebo/meshes/QCarWheel.stl</uri>
            </mesh>
          </geometry>
        </visual>
        <self_collide>0</self_collide>
        <enable_wind>0</enable_wind>
        <kinematic>0</kinematic>
      </link>
      <joint name='base_wheelrl_joint' type='revolute'>
        <pose relative_to='base'>-0.12765 0.0561 0.03338 0 -0 3.14</pose>
        <parent>base</parent>
        <child>wheelrl</child>
        <axis>
          <xyz>0 1 0</xyz>
          <limit>
            <lower>-1e+16</lower>
            <upper>1e+16</upper>
          </limit>
          <dynamics>
            <spring_reference>0</spring_reference>
            <spring_stiffness>0</spring_stiffness>
          </dynamics>
        </axis>
      </joint>
      <link name='wheelrl'>
        <pose relative_to='base_wheelrl_joint'>0 0 0 0 -0 0</pose>
        <inertial>
          <pose>0 0 0 0 -0 0</pose>
          <mass>0.1</mass>
          <inertia>
            <ixx>0.001</ixx>
            <ixy>0</ixy>
            <ixz>0</ixz>
            <iyy>0.001</iyy>
            <iyz>0</iyz>
            <izz>0.001</izz>
          </inertia>
        </inertial>
        <collision name='wheelrl_collision'>
          <pose>0 0 0 0 -0 0</pose>
          <geometry>
            <mesh>
              <scale>0.001 0.001 0.001</scale>
              <uri>/home/brent/Documents/autonomous-driving/ros/src/qcar_gazebo/meshes/QCarWheel.stl</uri>
            </mesh>
          </geometry>
          <max_contacts>10</max_contacts>
          <surface>
            <contact>
              <ode/>
            </contact>
            <bounce/>
            <friction>
              <torsional>
                <ode/>
              </torsional>
              <ode/>
            </friction>
          </surface>
        </collision>
        <visual name='wheelrl_visual'>
          <pose>0 0 0 0 -0 0</pose>
          <geometry>
            <mesh>
              <scale>0.001 0.001 0.001</scale>
              <uri>/home/brent/Documents/autonomous-driving/ros/src/qcar_gazebo/meshes/QCarWheel.stl</uri>
            </mesh>
          </geometry>
        </visual>
        <self_collide>0</self_collide>
        <enable_wind>0</enable_wind>
        <kinematic>0</kinematic>
      </link>
      <joint name='base_wheelrr_joint' type='revolute'>
        <pose relative_to='base'>-0.12765 -0.0561 0.03338 0 -0 0</pose>
        <parent>base</parent>
        <child>wheelrr</child>
        <axis>
          <xyz>0 1 0</xyz>
          <limit>
            <lower>-1e+16</lower>
            <upper>1e+16</upper>
          </limit>
          <dynamics>
            <spring_reference>0</spring_reference>
            <spring_stiffness>0</spring_stiffness>
          </dynamics>
        </axis>
      </joint>
      <link name='wheelrr'>
        <pose relative_to='base_wheelrr_joint'>0 0 0 0 -0 0</pose>
        <inertial>
          <pose>0 0 0 0 -0 0</pose>
          <mass>0.1</mass>
          <inertia>
            <ixx>0.001</ixx>
            <ixy>0</ixy>
            <ixz>0</ixz>
            <iyy>0.001</iyy>
            <iyz>0</iyz>
            <izz>0.001</izz>
          </inertia>
        </inertial>
        <collision name='wheelrr_collision'>
          <pose>0 0 0 0 -0 0</pose>
          <geometry>
            <mesh>
              <scale>0.001 0.001 0.001</scale>
              <uri>/home/brent/Documents/autonomous-driving/ros/src/qcar_gazebo/meshes/QCarWheel.stl</uri>
            </mesh>
          </geometry>
          <max_contacts>10</max_contacts>
          <surface>
            <contact>
              <ode/>
            </contact>
            <bounce/>
            <friction>
              <torsional>
                <ode/>
              </torsional>
              <ode/>
            </friction>
          </surface>
        </collision>
        <visual name='wheelrr_visual'>
          <pose>0 0 0 0 -0 0</pose>
          <geometry>
            <mesh>
              <scale>0.001 0.001 0.001</scale>
              <uri>/home/brent/Documents/autonomous-driving/ros/src/qcar_gazebo/meshes/QCarWheel.stl</uri>
            </mesh>
          </geometry>
        </visual>
        <self_collide>0</self_collide>
        <enable_wind>0</enable_wind>
        <kinematic>0</kinematic>
      </link>
      <joint name='body_lidar_joint' type='revolute'>
        <pose relative_to='base'>-0.01227 -0.00045 0.16152 0 -0 0</pose>
        <parent>base</parent>
        <child>lidar</child>
        <axis>
          <xyz>0 0 1</xyz>
          <limit>
            <lower>-1e+16</lower>
            <upper>1e+16</upper>
          </limit>
          <dynamics>
            <spring_reference>0</spring_reference>
            <spring_stiffness>0</spring_stiffness>
          </dynamics>
        </axis>
      </joint>
      <link name='lidar'>
        <pose relative_to='body_lidar_joint'>0 0 0 0 -0 0</pose>
        <inertial>
          <pose>0 0 0 0 -0 0</pose>
          <mass>0.1</mass>
          <inertia>
            <ixx>0.001</ixx>
            <ixy>0</ixy>
            <ixz>0</ixz>
            <iyy>0.001</iyy>
            <iyz>0</iyz>
            <izz>0.001</izz>
          </inertia>
        </inertial>
        <collision name='lidar_collision'>
          <pose>0 0 0 0 -0 0</pose>
          <geometry>
            <mesh>
              <scale>0.001 0.001 0.001</scale>
              <uri>/home/brent/Documents/autonomous-driving/ros/src/qcar_gazebo/meshes/QCarLidar.stl</uri>
            </mesh>
          </geometry>
          <max_contacts>10</max_contacts>
          <surface>
            <contact>
              <ode/>
            </contact>
            <bounce/>
            <friction>
              <torsional>
                <ode/>
              </torsional>
              <ode/>
            </friction>
          </surface>
        </collision>
        <visual name='lidar_visual'>
          <pose>0 0 0 0 -0 0</pose>
          <geometry>
            <mesh>
              <scale>0.001 0.001 0.001</scale>
              <uri>/home/brent/Documents/autonomous-driving/ros/src/qcar_gazebo/meshes/QCarLidar.stl</uri>
            </mesh>
          </geometry>
        </visual>
        <self_collide>0</self_collide>
        <enable_wind>0</enable_wind>
        <kinematic>0</kinematic>
      </link>
      <plugin name='camera' filename='librealsense_gazebo_plugin.so'>
        <prefix>camera</prefix>
        <depthUpdateRate>30.0</depthUpdateRate>
        <colorUpdateRate>30.0</colorUpdateRate>
        <infraredUpdateRate>30.0</infraredUpdateRate>
        <depthTopicName>depth/image_raw</depthTopicName>
        <depthCameraInfoTopicName>depth/camera_info</depthCameraInfoTopicName>
        <colorTopicName>color/image_raw</colorTopicName>
        <colorCameraInfoTopicName>color/camera_info</colorCameraInfoTopicName>
        <infrared1TopicName>infra1/image_raw</infrared1TopicName>
        <infrared1CameraInfoTopicName>infra1/camera_info</infrared1CameraInfoTopicName>
        <infrared2TopicName>infra2/image_raw</infrared2TopicName>
        <infrared2CameraInfoTopicName>infra2/camera_info</infrared2CameraInfoTopicName>
        <colorOpticalframeName>camera_color_optical_frame</colorOpticalframeName>
        <depthOpticalframeName>camera_depth_optical_frame</depthOpticalframeName>
        <infrared1OpticalframeName>camera_left_ir_optical_frame</infrared1OpticalframeName>
        <infrared2OpticalframeName>camera_right_ir_optical_frame</infrared2OpticalframeName>
        <rangeMinDepth>0.2</rangeMinDepth>
        <rangeMaxDepth>10.0</rangeMaxDepth>
        <pointCloud>1</pointCloud>
        <pointCloudTopicName>depth/color/points</pointCloudTopicName>
        <pointCloudCutoff>0.25</pointCloudCutoff>
        <pointCloudCutoffMax>9.0</pointCloudCutoffMax>
        <robotNamespace>/</robotNamespace>
      </plugin>
      <static>0</static>
      <plugin name='gazebo_ros_control' filename='libgazebo_ros_control.so'>
        <robotNamespace>/qcar</robotNamespace>
      </plugin>
      <pose>0 0 0 0 -0 0.5</pose>
    </model>
    <model name='Stop Sign'>
      <static>1</static>
      <link name='link'>
        <collision name='collision'>
          <geometry>
            <mesh>
              <uri>model://stop_sign/meshes/stop_sign.dae</uri>
            </mesh>
          </geometry>
          <max_contacts>10</max_contacts>
          <surface>
            <contact>
              <ode/>
            </contact>
            <bounce/>
            <friction>
              <torsional>
                <ode/>
              </torsional>
              <ode/>
            </friction>
          </surface>
        </collision>
        <visual name='visual'>
          <geometry>
            <mesh>
              <uri>model://stop_sign/meshes/stop_sign.dae</uri>
              <scale>0.5 0.5 0.5</scale>
            </mesh>
          </geometry>
          <material>
            <script>
              <uri>model://stop_sign/materials/scripts</uri>
              <uri>model://stop_sign/materials/textures</uri>
              <name>StopSign/Diffuse</name>
            </script>
          </material>
        </visual>
        <self_collide>0</self_collide>
        <enable_wind>0</enable_wind>
        <kinematic>0</kinematic>
      </link>
      <pose>4.99213 -0.732299 0 0 -0 0</pose>
    </model>
  </world>
</sdf>
