<?xml version='1.0'?>

<robot name="QCar" xmlns:xacro="http://www.ros.org/wiki/xacro">

  <xacro:include filename="$(find qcar)/urdf/materials.xacro" />
  <!-- <xacro:include filename="$(find qcar)/urdf/macros.xacro" /> -->
  <link name="base">
        <visual>
            <origin rpy="0 0 0" xyz="0 0 0"/>
            <geometry>
                <mesh filename="package://qcar/meshes/QCarBody.stl" scale="0.001 0.001 0.001"/>
            </geometry>
            <material name="white"/>
        </visual>
        <collision>
            <origin rpy="0 0 0" xyz="0 0 0"/>
            <geometry>
                <mesh filename="package://qcar/meshes/QCarBody.stl" scale="0.001 0.001 0.001"/>
            </geometry>
        </collision>
        <inertial>
            <origin rpy="0 0 0" xyz="0 0 0"/>
            <mass value="0.1"/>
            <inertia ixx="0.001" ixy="0" ixz="0" iyy="0.001" iyz="0" izz="0.001"/>
        </inertial>
    </link>
    <joint name="body_lidar_joint" type="continuous">
        <parent link="base"/>
        <child link="lidar"/>
        <origin rpy="0 0 0" xyz="-0.01227 -0.00045 0.16152"/>
        <axis xyz="0 0 1"/>
    </joint>
    <link name="lidar">
        <visual>
            <origin rpy="0 0 0" xyz="0 0 0"/>
            <geometry>
                <mesh filename="package://qcar/meshes/QCarLidar.stl" scale="0.001 0.001 0.001"/>
            </geometry>
            <material name="blue"/>
        </visual>
        <collision>
            <origin rpy="0 0 0" xyz="0 0 0"/>
            <geometry>
                <mesh filename="package://qcar/meshes/QCarLidar.stl" scale="0.001 0.001 0.001"/>
            </geometry>
        </collision>
        <inertial>
            <origin rpy="0 0 0" xyz="0 0 0"/>
            <mass value="0.1"/>
            <inertia ixx="0.001" ixy="0" ixz="0" iyy="0.001" iyz="0" izz="0.001"/>
        </inertial>
    </link>
    <joint name="base_hubfl_joint" type="revolute">
        <parent link="base"/>
        <child link="hubfl"/>
        <origin rpy="0 0 0" xyz="0.12960 0.05590 0.03338"/>
        <axis xyz="0 0 1"/>
        <dynamics damping="0.143" friction="0.0"/>
        <limit lower="-0.5236" upper="0.5236" effort="300" velocity="2"/>
    </joint>
    <link name="hubfl">
        <visual>
            <origin rpy="0 0 0" xyz="0 0 0"/>
            <geometry>
                <mesh filename="package://qcar/meshes/QCarSteeringHubL.stl" scale="0.001 0.001 0.001"/>
            </geometry>
            <material name="orange"/>
        </visual>
        <collision>
            <origin rpy="0 0 0" xyz="0 0 0"/>
            <geometry>
                <mesh filename="package://qcar/meshes/QCarSteeringHubL.stl" scale="0.001 0.001 0.001"/>
            </geometry>
        </collision>
        <inertial>
            <origin rpy="0 0 0" xyz="0 0 0"/>
            <mass value="0.1"/>
            <inertia ixx="0.001" ixy="0" ixz="0" iyy="0.001" iyz="0" izz="0.001"/>
        </inertial>
    </link>
    <joint name="base_hubfr_joint" type="revolute">
        <parent link="base"/>
        <child link="hubfr"/>
        <origin rpy="0 0 0" xyz="0.12960 -0.05590 0.03338"/>
        <axis xyz="0 0 1"/>
        <limit lower="-0.5236" upper="0.5236" effort="300" velocity="2"/>
        <dynamics damping="0.143" friction="0.0"/>
    </joint>
    <link name="hubfr">
        <visual>
            <origin rpy="0 0 0" xyz="0 0 0"/>
            <geometry>
                <mesh filename="package://qcar/meshes/QCarSteeringHubR.stl" scale="0.001 0.001 0.001"/>
            </geometry>
            <material name="orange"/>
        </visual>
        <collision>
            <origin rpy="0 0 0" xyz="0 0 0"/>
            <geometry>
                <mesh filename="package://qcar/meshes/QCarSteeringHubR.stl" scale="0.001 0.001 0.001"/>
            </geometry>
        </collision>
        <inertial>
            <origin rpy="0 0 0" xyz="0 0 0"/>
            <mass value="0.1"/>
            <inertia ixx="0.001" ixy="0" ixz="0" iyy="0.001" iyz="0" izz="0.001"/>
        </inertial>
    </link>
    <joint name="hubfl_wheelfl_joint" type="continuous">
        <parent link="hubfl"/>
        <child link="wheelfl"/>
        <origin rpy="0 0 3.14" xyz="0 0 0"/>
        <axis xyz="0 1 0"/>
    </joint>
    <link name="wheelfl">
        <visual>
            <origin rpy="0 0 0" xyz="0 0 0"/>
            <geometry>
                <mesh filename="package://qcar/meshes/QCarWheel.stl" scale="0.001 0.001 0.001"/>
            </geometry>
            <material name="red"/>
        </visual>
        <collision>
            <origin rpy="0 0 0" xyz="0 0 0"/>
            <geometry>
                <mesh filename="package://qcar/meshes/QCarWheel.stl" scale="0.001 0.001 0.001"/>
            </geometry>
        </collision>
        <inertial>
            <origin rpy="0 0 0" xyz="0 0 0"/>
            <mass value="0.1"/>
            <inertia ixx="0.001" ixy="0" ixz="0" iyy="0.001" iyz="0" izz="0.001"/>
        </inertial>
    </link>
    <joint name="hubfr_wheelfr_joint" type="continuous">
        <parent link="hubfr"/>
        <child link="wheelfr"/>
        <origin rpy="0 0 0" xyz="0 0 0"/>
        <axis xyz="0 1 0"/>
    </joint>
    <link name="wheelfr">
        <visual>
            <origin rpy="0 0 0" xyz="0 0 0"/>
            <geometry>
                <mesh filename="package://qcar/meshes/QCarWheel.stl" scale="0.001 0.001 0.001"/>
            </geometry>
            <material name="orange"/>
        </visual>
        <collision>
            <origin rpy="0 0 0" xyz="0 0 0"/>
            <geometry>
                <mesh filename="package://qcar/meshes/QCarWheel.stl" scale="0.001 0.001 0.001"/>
            </geometry>
        </collision>
        <inertial>
            <origin rpy="0 0 0" xyz="0 0 0"/>
            <mass value="0.1"/>
            <inertia ixx="0.001" ixy="0" ixz="0" iyy="0.001" iyz="0" izz="0.001"/>
        </inertial>
    </link>

    <joint name="base_wheelrl_joint" type="continuous">
        <parent link="base"/>
        <child link="wheelrl"/>
        <origin rpy="0 0 3.14" xyz="-0.12765 0.05610 0.03338"/>
        <axis xyz="0 1 0"/>
    </joint>
    <link name="wheelrl">
        <visual>
            <origin rpy="0 0 0" xyz="0 0 0"/>
            <geometry>
                <mesh filename="package://qcar/meshes/QCarWheel.stl" scale="0.001 0.001 0.001"/>
            </geometry>
            <material name="orange"/>
        </visual>
        <collision>
            <origin rpy="0 0 0" xyz="0 0 0"/>
            <geometry>
                <mesh filename="package://qcar/meshes/QCarWheel.stl" scale="0.001 0.001 0.001"/>
            </geometry>
        </collision>
        <inertial>
            <origin rpy="0 0 0" xyz="0 0 0"/>
            <mass value="0.1"/>
            <inertia ixx="0.001" ixy="0" ixz="0" iyy="0.001" iyz="0" izz="0.001"/>
        </inertial>
    </link>

    <joint name="base_wheelrr_joint" type="continuous">
        <parent link="base"/>
        <child link="wheelrr"/>
        <origin rpy="0 0 0" xyz="-0.12765 -0.05610 0.03338"/>
        <axis xyz="0 1 0"/>
    </joint>
    <link name="wheelrr">
        <visual>
            <origin rpy="0 0 0" xyz="0 0 0"/>    
            <geometry>
                <mesh filename="package://qcar/meshes/QCarWheel.stl" scale="0.001 0.001 0.001"/>
            </geometry>
            <material name="red"/>
        </visual>
        <collision>
            <origin rpy="0 0 0" xyz="0 0 0"/>
            <geometry>
                <mesh filename="package://qcar/meshes/QCarWheel.stl" scale="0.001 0.001 0.001"/>
            </geometry>
        </collision>
        <inertial>
            <origin rpy="0 0 0" xyz="0 0 0"/>
            <mass value="0.1"/>
            <inertia ixx="0.001" ixy="0" ixz="0" iyy="0.001" iyz="0" izz="0.001"/>
        </inertial>
    </link>

    <joint name="camera_rgb_joint" type="fixed">
	    <!-- <axis xyz="0 1 0" /> -->
	    <!-- <origin xyz=".2 0 0" rpy="0 0 0"/> -->
        <origin rpy="0 0 0" xyz="0.081686 0.031547 0.15445"/>
        <!-- <origin rpy="0 0 0" xyz="0 0 0"/> -->
	    <parent link="base"/>
	    <child link="camera_rgb"/>
  	</joint>
    <link name="camera_rgb"/>

    <joint name="camera_csi_front_joint" type="fixed">
        <!-- <axis xyz="0 1 0" /> -->
        <!-- <origin xyz=".2 0 0" rpy="0 0 0"/> -->
        <origin rpy="0 0 0" xyz="0.19236 -0.000475 0.093029"/>
        <!-- <origin rpy="0 0 0" xyz="0 0 0"/> -->
        <parent link="base"/>
        <child link="camera_csi_front"/>
    </joint>
    <link name="camera_csi_front"/>

    <joint name="camera_csi_right_joint" type="fixed">
        <!-- <axis xyz="0 1 0" /> -->
        <!-- <origin xyz=".2 0 0" rpy="0 0 0"/> -->
        <origin rpy="0 0 -1.5708" xyz="0.12887 -0.06755 0.093029"/>
        <!-- <origin rpy="0 0 0" xyz="0 0 0"/> -->
        <parent link="base"/>
        <child link="camera_csi_right"/>
    </joint>
    <link name="camera_csi_right"/>

    <joint name="camera_csi_back_joint" type="fixed">
        <!-- <axis xyz="0 1 0" /> -->
        <!-- <origin xyz=".2 0 0" rpy="0 0 0"/> -->
        <origin rpy="0 0 -3.1416" xyz="-0.16669 -0.000578 0.093029"/>
        <!-- <origin rpy="0 0 0" xyz="0 0 0"/> -->
        <parent link="base"/>
        <child link="camera_csi_back"/>
    </joint>
    <link name="camera_csi_back"/>

    <joint name="camera_csi_left_joint" type="fixed">
        <!-- <axis xyz="0 1 0" /> -->
        <!-- <origin xyz=".2 0 0" rpy="0 0 0"/> -->
        <origin rpy="0 0 1.5708" xyz="0.12784 0.052497 0.093029"/>
        <!-- <origin rpy="0 0 0" xyz="0 0 0"/> -->
        <parent link="base"/>
        <child link="camera_csi_left"/>
    </joint>
    <link name="camera_csi_left"/>

    <transmission name="body_lidar_tran">
        <type>>transmission_interface/SimpleTransmission</type>
        <joint name="body_lidar_joint">
            <hardwareInterface>hardware_interface/EffortJointInterface</hardwareInterface>
        </joint>
        <actuator name="body_lidar_motor">
            <mechanicalReduction>1</mechanicalReduction>
        </actuator>
    </transmission>

    <transmission name="base_hubfl_tran">
        <type>>transmission_interface/SimpleTransmission</type>
        <joint name="base_hubfl_joint">
            <hardwareInterface>hardware_interface/EffortJointInterface</hardwareInterface>
        </joint>
        <actuator name="base_hubfl_motor">
            <mechanicalReduction>1</mechanicalReduction>
        </actuator>
    </transmission>
    <transmission name="base_hubfr_tran">
        <type>>transmission_interface/SimpleTransmission</type>
        <joint name="base_hubfr_joint">
            <hardwareInterface>hardware_interface/EffortJointInterface</hardwareInterface>
        </joint>
        <actuator name="base_hubfr_motor">
            <mechanicalReduction>1</mechanicalReduction>
        </actuator>
    </transmission>

    <transmission name="hubfl_wheelfl_tran">
        <type>>transmission_interface/SimpleTransmission</type>
        <joint name="hubfl_wheelfl_joint">
            <hardwareInterface>hardware_interface/EffortJointInterface</hardwareInterface>
        </joint>
        <actuator name="hubfl_wheelfl_motor">
            <mechanicalReduction>1</mechanicalReduction>
        </actuator>
    </transmission>
    <transmission name="hubfr_wheelfr_tran">
        <type>>transmission_interface/SimpleTransmission</type>
        <joint name="hubfr_wheelfr_joint">
            <hardwareInterface>hardware_interface/EffortJointInterface</hardwareInterface>
        </joint>
        <actuator name="hubfr_wheelfr_motor">
            <mechanicalReduction>1</mechanicalReduction>
        </actuator>
    </transmission>

    <transmission name="base_wheelrl_tran">
        <type>>transmission_interface/SimpleTransmission</type>
        <joint name="base_wheelrl_joint">
            <hardwareInterface>hardware_interface/EffortJointInterface</hardwareInterface>
        </joint>
        <actuator name="base_wheelrl_motor">
            <mechanicalReduction>1</mechanicalReduction>
        </actuator>
    </transmission>
    <transmission name="base_wheelrr_tran">
        <type>>transmission_interface/SimpleTransmission</type>
        <joint name="base_wheelrr_joint">
            <hardwareInterface>hardware_interface/EffortJointInterface</hardwareInterface>
        </joint>
        <actuator name="base_wheelrr_motor">
            <mechanicalReduction>1</mechanicalReduction>
        </actuator>
    </transmission>


  </robot>
  



